[2019-05-19 04:35:11 +0000] [24877] [ERROR] Exception in worker process
Traceback (most recent call last):
  File "/home/personalweb/local/lib/python2.7/site-packages/gunicorn/arbiter.py", line 583, in spawn_worker
    worker.init_process()
  File "/home/personalweb/local/lib/python2.7/site-packages/gunicorn/workers/base.py", line 129, in init_process
    self.load_wsgi()
  File "/home/personalweb/local/lib/python2.7/site-packages/gunicorn/workers/base.py", line 138, in load_wsgi
    self.wsgi = self.app.wsgi()
  File "/home/personalweb/local/lib/python2.7/site-packages/gunicorn/app/base.py", line 67, in wsgi
    self.callable = self.load()
  File "/home/personalweb/local/lib/python2.7/site-packages/gunicorn/app/wsgiapp.py", line 52, in load
    return self.load_wsgiapp()
  File "/home/personalweb/local/lib/python2.7/site-packages/gunicorn/app/wsgiapp.py", line 41, in load_wsgiapp
    return util.import_app(self.app_uri)
  File "/home/personalweb/local/lib/python2.7/site-packages/gunicorn/util.py", line 350, in import_app
    __import__(module)
ImportError: No module named personalweb2.wsgi
[2019-05-19 04:35:12 +0000] [24884] [ERROR] Exception in worker process
Traceback (most recent call last):
  File "/home/personalweb/local/lib/python2.7/site-packages/gunicorn/arbiter.py", line 583, in spawn_worker
    worker.init_process()
  File "/home/personalweb/local/lib/python2.7/site-packages/gunicorn/workers/base.py", line 129, in init_process
    self.load_wsgi()
  File "/home/personalweb/local/lib/python2.7/site-packages/gunicorn/workers/base.py", line 138, in load_wsgi
    self.wsgi = self.app.wsgi()
  File "/home/personalweb/local/lib/python2.7/site-packages/gunicorn/app/base.py", line 67, in wsgi
    self.callable = self.load()
  File "/home/personalweb/local/lib/python2.7/site-packages/gunicorn/app/wsgiapp.py", line 52, in load
    return self.load_wsgiapp()
  File "/home/personalweb/local/lib/python2.7/site-packages/gunicorn/app/wsgiapp.py", line 41, in load_wsgiapp
    return util.import_app(self.app_uri)
  File "/home/personalweb/local/lib/python2.7/site-packages/gunicorn/util.py", line 350, in import_app
    __import__(module)
ImportError: No module named personalweb2.wsgi
[2019-05-19 04:35:15 +0000] [24891] [ERROR] Exception in worker process
Traceback (most recent call last):
  File "/home/personalweb/local/lib/python2.7/site-packages/gunicorn/arbiter.py", line 583, in spawn_worker
    worker.init_process()
  File "/home/personalweb/local/lib/python2.7/site-packages/gunicorn/workers/base.py", line 129, in init_process
    self.load_wsgi()
  File "/home/personalweb/local/lib/python2.7/site-packages/gunicorn/workers/base.py", line 138, in load_wsgi
    self.wsgi = self.app.wsgi()
  File "/home/personalweb/local/lib/python2.7/site-packages/gunicorn/app/base.py", line 67, in wsgi
    self.callable = self.load()
  File "/home/personalweb/local/lib/python2.7/site-packages/gunicorn/app/wsgiapp.py", line 52, in load
    return self.load_wsgiapp()
  File "/home/personalweb/local/lib/python2.7/site-packages/gunicorn/app/wsgiapp.py", line 41, in load_wsgiapp
    return util.import_app(self.app_uri)
  File "/home/personalweb/local/lib/python2.7/site-packages/gunicorn/util.py", line 350, in import_app
    __import__(module)
ImportError: No module named personalweb2.wsgi
[2019-05-19 04:35:18 +0000] [24898] [ERROR] Exception in worker process
Traceback (most recent call last):
  File "/home/personalweb/local/lib/python2.7/site-packages/gunicorn/arbiter.py", line 583, in spawn_worker
    worker.init_process()
  File "/home/personalweb/local/lib/python2.7/site-packages/gunicorn/workers/base.py", line 129, in init_process
    self.load_wsgi()
  File "/home/personalweb/local/lib/python2.7/site-packages/gunicorn/workers/base.py", line 138, in load_wsgi
    self.wsgi = self.app.wsgi()
  File "/home/personalweb/local/lib/python2.7/site-packages/gunicorn/app/base.py", line 67, in wsgi
    self.callable = self.load()
  File "/home/personalweb/local/lib/python2.7/site-packages/gunicorn/app/wsgiapp.py", line 52, in load
    return self.load_wsgiapp()
  File "/home/personalweb/local/lib/python2.7/site-packages/gunicorn/app/wsgiapp.py", line 41, in load_wsgiapp
    return util.import_app(self.app_uri)
  File "/home/personalweb/local/lib/python2.7/site-packages/gunicorn/util.py", line 350, in import_app
    __import__(module)
ImportError: No module named personalweb2.wsgi
[2019-05-19 04:35:18 +0000] [24899] [ERROR] Exception in worker process
Traceback (most recent call last):
  File "/home/personalweb/local/lib/python2.7/site-packages/gunicorn/arbiter.py", line 583, in spawn_worker
    worker.init_process()
  File "/home/personalweb/local/lib/python2.7/site-packages/gunicorn/workers/base.py", line 129, in init_process
    self.load_wsgi()
  File "/home/personalweb/local/lib/python2.7/site-packages/gunicorn/workers/base.py", line 138, in load_wsgi
    self.wsgi = self.app.wsgi()
  File "/home/personalweb/local/lib/python2.7/site-packages/gunicorn/app/base.py", line 67, in wsgi
    self.callable = self.load()
  File "/home/personalweb/local/lib/python2.7/site-packages/gunicorn/app/wsgiapp.py", line 52, in load
    return self.load_wsgiapp()
  File "/home/personalweb/local/lib/python2.7/site-packages/gunicorn/app/wsgiapp.py", line 41, in load_wsgiapp
    return util.import_app(self.app_uri)
  File "/home/personalweb/local/lib/python2.7/site-packages/gunicorn/util.py", line 350, in import_app
    __import__(module)
ImportError: No module named personalweb2.wsgi
[2019-05-19 04:35:18 +0000] [24900] [ERROR] Exception in worker process
Traceback (most recent call last):
  File "/home/personalweb/local/lib/python2.7/site-packages/gunicorn/arbiter.py", line 583, in spawn_worker
    worker.init_process()
  File "/home/personalweb/local/lib/python2.7/site-packages/gunicorn/workers/base.py", line 129, in init_process
    self.load_wsgi()
  File "/home/personalweb/local/lib/python2.7/site-packages/gunicorn/workers/base.py", line 138, in load_wsgi
    self.wsgi = self.app.wsgi()
  File "/home/personalweb/local/lib/python2.7/site-packages/gunicorn/app/base.py", line 67, in wsgi
    self.callable = self.load()
  File "/home/personalweb/local/lib/python2.7/site-packages/gunicorn/app/wsgiapp.py", line 52, in load
    return self.load_wsgiapp()
  File "/home/personalweb/local/lib/python2.7/site-packages/gunicorn/app/wsgiapp.py", line 41, in load_wsgiapp
    return util.import_app(self.app_uri)
  File "/home/personalweb/local/lib/python2.7/site-packages/gunicorn/util.py", line 350, in import_app
    __import__(module)
ImportError: No module named personalweb2.wsgi
[2019-05-19 15:07:33 +0000] [1182] [ERROR] Exception in worker process
Traceback (most recent call last):
  File "/home/personalweb/local/lib/python2.7/site-packages/gunicorn/arbiter.py", line 583, in spawn_worker
    worker.init_process()
  File "/home/personalweb/local/lib/python2.7/site-packages/gunicorn/workers/base.py", line 129, in init_process
    self.load_wsgi()
  File "/home/personalweb/local/lib/python2.7/site-packages/gunicorn/workers/base.py", line 138, in load_wsgi
    self.wsgi = self.app.wsgi()
  File "/home/personalweb/local/lib/python2.7/site-packages/gunicorn/app/base.py", line 67, in wsgi
    self.callable = self.load()
  File "/home/personalweb/local/lib/python2.7/site-packages/gunicorn/app/wsgiapp.py", line 52, in load
    return self.load_wsgiapp()
  File "/home/personalweb/local/lib/python2.7/site-packages/gunicorn/app/wsgiapp.py", line 41, in load_wsgiapp
    return util.import_app(self.app_uri)
  File "/home/personalweb/local/lib/python2.7/site-packages/gunicorn/util.py", line 350, in import_app
    __import__(module)
ImportError: No module named personal_website.wsgi
[2019-05-19 15:07:33 +0000] [1185] [ERROR] Exception in worker process
Traceback (most recent call last):
  File "/home/personalweb/local/lib/python2.7/site-packages/gunicorn/arbiter.py", line 583, in spawn_worker
    worker.init_process()
  File "/home/personalweb/local/lib/python2.7/site-packages/gunicorn/workers/base.py", line 129, in init_process
    self.load_wsgi()
  File "/home/personalweb/local/lib/python2.7/site-packages/gunicorn/workers/base.py", line 138, in load_wsgi
    self.wsgi = self.app.wsgi()
  File "/home/personalweb/local/lib/python2.7/site-packages/gunicorn/app/base.py", line 67, in wsgi
    self.callable = self.load()
  File "/home/personalweb/local/lib/python2.7/site-packages/gunicorn/app/wsgiapp.py", line 52, in load
    return self.load_wsgiapp()
  File "/home/personalweb/local/lib/python2.7/site-packages/gunicorn/app/wsgiapp.py", line 41, in load_wsgiapp
    return util.import_app(self.app_uri)
  File "/home/personalweb/local/lib/python2.7/site-packages/gunicorn/util.py", line 350, in import_app
    __import__(module)
ImportError: No module named personal_website.wsgi
[2019-05-19 15:07:33 +0000] [1186] [ERROR] Exception in worker process
Traceback (most recent call last):
  File "/home/personalweb/local/lib/python2.7/site-packages/gunicorn/arbiter.py", line 583, in spawn_worker
    worker.init_process()
  File "/home/personalweb/local/lib/python2.7/site-packages/gunicorn/workers/base.py", line 129, in init_process
    self.load_wsgi()
  File "/home/personalweb/local/lib/python2.7/site-packages/gunicorn/workers/base.py", line 138, in load_wsgi
    self.wsgi = self.app.wsgi()
  File "/home/personalweb/local/lib/python2.7/site-packages/gunicorn/app/base.py", line 67, in wsgi
    self.callable = self.load()
  File "/home/personalweb/local/lib/python2.7/site-packages/gunicorn/app/wsgiapp.py", line 52, in load
    return self.load_wsgiapp()
  File "/home/personalweb/local/lib/python2.7/site-packages/gunicorn/app/wsgiapp.py", line 41, in load_wsgiapp
    return util.import_app(self.app_uri)
  File "/home/personalweb/local/lib/python2.7/site-packages/gunicorn/util.py", line 350, in import_app
    __import__(module)
ImportError: No module named personal_website.wsgi
[2019-05-19 15:07:35 +0000] [1233] [ERROR] Exception in worker process
Traceback (most recent call last):
  File "/home/personalweb/local/lib/python2.7/site-packages/gunicorn/arbiter.py", line 583, in spawn_worker
    worker.init_process()
  File "/home/personalweb/local/lib/python2.7/site-packages/gunicorn/workers/base.py", line 129, in init_process
    self.load_wsgi()
  File "/home/personalweb/local/lib/python2.7/site-packages/gunicorn/workers/base.py", line 138, in load_wsgi
    self.wsgi = self.app.wsgi()
  File "/home/personalweb/local/lib/python2.7/site-packages/gunicorn/app/base.py", line 67, in wsgi
    self.callable = self.load()
  File "/home/personalweb/local/lib/python2.7/site-packages/gunicorn/app/wsgiapp.py", line 52, in load
    return self.load_wsgiapp()
  File "/home/personalweb/local/lib/python2.7/site-packages/gunicorn/app/wsgiapp.py", line 41, in load_wsgiapp
    return util.import_app(self.app_uri)
  File "/home/personalweb/local/lib/python2.7/site-packages/gunicorn/util.py", line 350, in import_app
    __import__(module)
ImportError: No module named personal_website.wsgi
[2019-05-19 15:07:35 +0000] [1245] [ERROR] Exception in worker process
Traceback (most recent call last):
  File "/home/personalweb/local/lib/python2.7/site-packages/gunicorn/arbiter.py", line 583, in spawn_worker
    worker.init_process()
  File "/home/personalweb/local/lib/python2.7/site-packages/gunicorn/workers/base.py", line 129, in init_process
    self.load_wsgi()
  File "/home/personalweb/local/lib/python2.7/site-packages/gunicorn/workers/base.py", line 138, in load_wsgi
    self.wsgi = self.app.wsgi()
  File "/home/personalweb/local/lib/python2.7/site-packages/gunicorn/app/base.py", line 67, in wsgi
    self.callable = self.load()
  File "/home/personalweb/local/lib/python2.7/site-packages/gunicorn/app/wsgiapp.py", line 52, in load
    return self.load_wsgiapp()
  File "/home/personalweb/local/lib/python2.7/site-packages/gunicorn/app/wsgiapp.py", line 41, in load_wsgiapp
    return util.import_app(self.app_uri)
  File "/home/personalweb/local/lib/python2.7/site-packages/gunicorn/util.py", line 350, in import_app
    __import__(module)
ImportError: No module named personal_website.wsgi
[2019-05-19 15:07:35 +0000] [1246] [ERROR] Exception in worker process
Traceback (most recent call last):
  File "/home/personalweb/local/lib/python2.7/site-packages/gunicorn/arbiter.py", line 583, in spawn_worker
    worker.init_process()
  File "/home/personalweb/local/lib/python2.7/site-packages/gunicorn/workers/base.py", line 129, in init_process
    self.load_wsgi()
  File "/home/personalweb/local/lib/python2.7/site-packages/gunicorn/workers/base.py", line 138, in load_wsgi
    self.wsgi = self.app.wsgi()
  File "/home/personalweb/local/lib/python2.7/site-packages/gunicorn/app/base.py", line 67, in wsgi
    self.callable = self.load()
  File "/home/personalweb/local/lib/python2.7/site-packages/gunicorn/app/wsgiapp.py", line 52, in load
    return self.load_wsgiapp()
  File "/home/personalweb/local/lib/python2.7/site-packages/gunicorn/app/wsgiapp.py", line 41, in load_wsgiapp
    return util.import_app(self.app_uri)
  File "/home/personalweb/local/lib/python2.7/site-packages/gunicorn/util.py", line 350, in import_app
    __import__(module)
ImportError: No module named personal_website.wsgi
[2019-05-19 15:07:38 +0000] [1273] [ERROR] Exception in worker process
Traceback (most recent call last):
  File "/home/personalweb/local/lib/python2.7/site-packages/gunicorn/arbiter.py", line 583, in spawn_worker
    worker.init_process()
  File "/home/personalweb/local/lib/python2.7/site-packages/gunicorn/workers/base.py", line 129, in init_process
    self.load_wsgi()
  File "/home/personalweb/local/lib/python2.7/site-packages/gunicorn/workers/base.py", line 138, in load_wsgi
    self.wsgi = self.app.wsgi()
  File "/home/personalweb/local/lib/python2.7/site-packages/gunicorn/app/base.py", line 67, in wsgi
    self.callable = self.load()
  File "/home/personalweb/local/lib/python2.7/site-packages/gunicorn/app/wsgiapp.py", line 52, in load
    return self.load_wsgiapp()
  File "/home/personalweb/local/lib/python2.7/site-packages/gunicorn/app/wsgiapp.py", line 41, in load_wsgiapp
    return util.import_app(self.app_uri)
  File "/home/personalweb/local/lib/python2.7/site-packages/gunicorn/util.py", line 350, in import_app
    __import__(module)
ImportError: No module named personal_website.wsgi
[2019-05-19 15:07:38 +0000] [1274] [ERROR] Exception in worker process
Traceback (most recent call last):
  File "/home/personalweb/local/lib/python2.7/site-packages/gunicorn/arbiter.py", line 583, in spawn_worker
    worker.init_process()
  File "/home/personalweb/local/lib/python2.7/site-packages/gunicorn/workers/base.py", line 129, in init_process
    self.load_wsgi()
  File "/home/personalweb/local/lib/python2.7/site-packages/gunicorn/workers/base.py", line 138, in load_wsgi
    self.wsgi = self.app.wsgi()
  File "/home/personalweb/local/lib/python2.7/site-packages/gunicorn/app/base.py", line 67, in wsgi
    self.callable = self.load()
  File "/home/personalweb/local/lib/python2.7/site-packages/gunicorn/app/wsgiapp.py", line 52, in load
    return self.load_wsgiapp()
  File "/home/personalweb/local/lib/python2.7/site-packages/gunicorn/app/wsgiapp.py", line 41, in load_wsgiapp
    return util.import_app(self.app_uri)
  File "/home/personalweb/local/lib/python2.7/site-packages/gunicorn/util.py", line 350, in import_app
    __import__(module)
ImportError: No module named personal_website.wsgi
[2019-05-19 15:07:41 +0000] [1281] [ERROR] Exception in worker process
Traceback (most recent call last):
  File "/home/personalweb/local/lib/python2.7/site-packages/gunicorn/arbiter.py", line 583, in spawn_worker
    worker.init_process()
  File "/home/personalweb/local/lib/python2.7/site-packages/gunicorn/workers/base.py", line 129, in init_process
    self.load_wsgi()
  File "/home/personalweb/local/lib/python2.7/site-packages/gunicorn/workers/base.py", line 138, in load_wsgi
    self.wsgi = self.app.wsgi()
  File "/home/personalweb/local/lib/python2.7/site-packages/gunicorn/app/base.py", line 67, in wsgi
    self.callable = self.load()
  File "/home/personalweb/local/lib/python2.7/site-packages/gunicorn/app/wsgiapp.py", line 52, in load
    return self.load_wsgiapp()
  File "/home/personalweb/local/lib/python2.7/site-packages/gunicorn/app/wsgiapp.py", line 41, in load_wsgiapp
    return util.import_app(self.app_uri)
  File "/home/personalweb/local/lib/python2.7/site-packages/gunicorn/util.py", line 350, in import_app
    __import__(module)
ImportError: No module named personal_website.wsgi
